<mujoco model="bot_elf">
  <compiler angle="radian" meshdir="meshes" autolimits="true"/>

  <default>
    <light castshadow="false" />

    <default class="visual">
        <geom contype="0" conaffinity="0"/>
    </default>

    <default class="collision">
        <geom contype="1" conaffinity="1"/>
    </default>

    <joint damping="0.1" armature="0.01" frictionloss="0.01" />

    <geom friction="0.9 0.8 0.8" contype="0" conaffinity="0"/>
  </default>

  <visual>
    <rgba com="0.502 1.0 0 1.0" fog="0 0 0 1" contactpoint="0.4 0.4 0.4 0.8"
      contactforce="0.0 0.9 0.9 0.5" />
    <scale com="0.05" forcewidth="0.04" contactwidth="0.10" contactheight="0.005" selectpoint="0.01" />
    <map force="0.005" />
  </visual>

  <option timestep="0.0005" />

  <asset>
    <mesh name="base_link" file="base_link.STL"/>
    <mesh name="l_hip_z_link" file="l_hip_z_link.STL"/>
    <mesh name="l_hip_x_link" file="l_hip_x_link.STL"/>
    <mesh name="l_hip_y_link" file="l_hip_y_link.STL"/>
    <mesh name="l_knee_y_link" file="l_knee_y_link.STL"/>
    <mesh name="l_ankle_y_link" file="l_ankle_y_link.STL"/>
    <mesh name="l_ankle_x_link" file="l_ankle_x_link.STL"/>
    <mesh name="r_hip_z_link" file="r_hip_z_link.STL"/>
    <mesh name="r_hip_x_link" file="r_hip_x_link.STL"/>
    <mesh name="r_hip_y_link" file="r_hip_y_link.STL"/>
    <mesh name="r_knee_y_link" file="r_knee_y_link.STL"/>
    <mesh name="r_ankle_y_link" file="r_ankle_y_link.STL"/>
    <mesh name="r_ankle_x_link" file="r_ankle_x_link.STL"/>
    <mesh name="l_shld_y_link" file="l_shld_y_link.STL"/>
    <mesh name="l_shld_x_link" file="l_shld_x_link.STL"/>
    <mesh name="l_shld_z_link" file="l_shld_z_link.STL"/>
    <mesh name="l_elb_y_link" file="l_elb_y_link.STL"/>
    <mesh name="r_shld_y_link" file="r_shld_y_link.STL"/>
    <mesh name="r_shld_x_link" file="r_shld_x_link.STL"/>
    <mesh name="r_shld_z_link" file="r_shld_z_link.STL"/>
    <mesh name="r_elb_y_link" file="r_elb_y_link.STL"/>

    <texture type="skybox" builtin="gradient" width="512" height="512" rgb1=".4 .6 .8"
        rgb2="0 0 0" />
    <texture name="texgeom" type="cube" builtin="flat" mark="cross" width="128"
        height="128"
        rgb1="0.6 0.6 0.6" rgb2="0.6 0.6 0.6" markrgb="1 1 1" />
    <texture name="texplane" type="2d" builtin="checker" rgb1=".4 .4 .4" rgb2=".6 .6 .6"
        width="512" height="512" />
    <material name='MatPlane' reflectance='0.3' texture="texplane" texrepeat="1 1"
        texuniform="true"
        rgba=".7 .7 .7 1" />
  </asset>

  <worldbody>
    <light directional="true" diffuse=".8 .8 .8" pos="0 0 10" dir="0 0 -10" />
    <geom class="collision" name="floor" pos="0 0 0" type="plane" size="0 0 1" material="MatPlane" />
    <camera name="track" mode="targetbody" target="base_link" pos="0 -1.3 1.6"
        xyaxes="1 0 0 0 0.707 0.707" />

    <body name="base_link" pos="0 0 0.95" gravcomp="0">
      <inertial pos="0.00480846 0.00243995 0.00377326" quat="0.999995 2.89561e-05 0.00312534 0.00110843" mass="8.50938" diaginertia="0.263605 0.212141 0.0716387"/>
      <joint name="world_joint" type="free"/>
      <geom class="collision" type="mesh" rgba="0.75294 0.75294 0.75294 1" mesh="base_link"/>
      <site name="imu" pos="0 0 0" />
      <body name="l_hip_z_link" pos="0 0.1 -0.2929" gravcomp="0">
        <inertial pos="-0.0926596 1.831e-05 0.0133358" quat="0.954084 -0.000917214 0.299524 -0.00294749" mass="1.23681" diaginertia="0.00340136 0.00310784 0.00119479"/>
        <joint name="l_hip_z_joint" pos="0 0 0" axis="0 0 1" range="-0.785 0.785"/>
        <geom type="mesh" rgba="0.752941 0.752941 0.752941 1" mesh="l_hip_z_link"/>
        <body name="l_hip_x_link" pos="0 0 0" gravcomp="0">
          <inertial pos="-0.00295307 -0.0473123 4.49e-06" quat="0.547733 0.548351 0.447112 0.446531" mass="1.74957" diaginertia="0.00322536 0.00240539 0.00202647"/>
          <joint name="l_hip_x_joint" pos="0 0 0" axis="1 0 0" range="-0.523 0.785"/>
          <geom type="mesh" rgba="0.752941 0.752941 0.752941 1" mesh="l_hip_x_link"/>
          <body name="l_hip_y_link" pos="0 0 0" gravcomp="0">
            <inertial pos="0.00255763 0.0236405 -0.0488087" quat="0.757333 -0.0675707 0.0350565 0.648577" mass="2.50087" diaginertia="0.0254053 0.0251293 0.00362058"/>
            <joint name="l_hip_y_joint" pos="0 0 0" axis="0 1 0" range="-2 0.5"/>
            <geom type="mesh" rgba="0.752941 0.752941 0.752941 1" mesh="l_hip_y_link"/>
            <body name="l_knee_y_link" pos="0 0 -0.3" gravcomp="0">
              <inertial pos="0.00659759 0.00057144 -0.109687" quat="0.999522 -0.00929623 0.0275842 0.0103702" mass="1.58922" diaginertia="0.0096954 0.00947624 0.00122694"/>
              <joint name="l_knee_y_joint" pos="0 0 0" axis="0 1 0" range="0 2.2"/>
              <geom type="mesh" rgba="0.752941 0.752941 0.752941 1" mesh="l_knee_y_link"/>
              <body name="l_ankle_y_link" pos="0 0 -0.3" gravcomp="0">
                <inertial pos="0 0 0" quat="0.5 0.5 -0.5 0.5" mass="0.0230716" diaginertia="3.67e-06 2.87e-06 1.54e-06"/>
                <joint name="l_ankle_y_joint" pos="0 0 0" axis="0 1 0" range="-1.134 0.872"/>
                <body name="l_ankle_x_link" pos="0 0 0" gravcomp="0">
                  <inertial pos="-0.00029962 0 -0.0261501" quat="0 0.708307 0 0.705905" mass="0.364824" diaginertia="0.00110975 0.00091946 0.00022373"/>
                  <joint name="l_ankle_x_joint" pos="0 0 0" axis="1 0 0" range="-0.349 0.349"/>
                  <geom class="collision" name="l_foot_1" size="0.01 0.085" pos="0 0.04 -0.03" quat="0.707105 0 0.707108 0" type="capsule" rgba="0.752941 0.752941 0.752941 1"/>
                  <geom class="collision" name="l_foot_2" size="0.01 0.085" pos="0 -0.04 -0.03" quat="0.707105 0 0.707108 0" type="capsule" rgba="0.752941 0.752941 0.752941 1"/>
                  <!-- <site name="lf_tc" type="box" class="collision" size="0.09 0.043 0.005" pos="0.0 0 -0.035" rgba="1 1 1 1" /> -->
                  <site name="lf_tc" type="box" class="collision" size="0.09 0.043 0.005" pos="0.0 0 -0.035" rgba="0 0 0 0"/>
                </body>
              </body>
            </body>
          </body>
        </body>
      </body>
      <body name="r_hip_z_link" pos="0 -0.1 -0.2929" gravcomp="0">
        <inertial pos="-0.0926596 -1.831e-05 0.0133358" quat="0.954084 0.000917214 0.299524 0.00294749" mass="1.23681" diaginertia="0.00340136 0.00310784 0.00119479"/>
        <joint name="r_hip_z_joint" pos="0 0 0" axis="0 0 1" range="-0.785 0.785"/>
        <geom type="mesh" rgba="0.752941 0.752941 0.752941 1" mesh="r_hip_z_link"/>
        <body name="r_hip_x_link" pos="0 0 0" gravcomp="0">
          <inertial pos="-0.00295307 0.0473123 -4.49e-06" quat="0.447112 0.446531 0.547733 0.548351" mass="1.74957" diaginertia="0.00322536 0.00240539 0.00202647"/>
          <joint name="r_hip_x_joint" pos="0 0 0" axis="1 0 0" range="-0.785 0.523"/>
          <geom type="mesh" rgba="0.752941 0.752941 0.752941 1" mesh="r_hip_x_link"/>
          <body name="r_hip_y_link" pos="0 0 0" gravcomp="0">
            <inertial pos="0.00255763 -0.0236405 -0.0488088" quat="0.648576 0.0350562 -0.0675708 0.757334" mass="2.50087" diaginertia="0.0254053 0.0251294 0.00362059"/>
            <joint name="r_hip_y_joint" pos="0 0 0" axis="0 1 0" range="-2 0.5"/>
            <geom type="mesh" rgba="0.752941 0.752941 0.752941 1" mesh="r_hip_y_link"/>
            <body name="r_knee_y_link" pos="0 0 -0.3" gravcomp="0">
              <inertial pos="0.00660983 -0.00055456 -0.109637" quat="0.999532 0.00944127 0.0275094 -0.00947171" mass="1.58818" diaginertia="0.00968261 0.00946404 0.00122593"/>
              <joint name="r_knee_y_joint" pos="0 0 0" axis="0 1 0" range="0 2.2"/>
              <geom type="mesh" rgba="0.752941 0.752941 0.752941 1" mesh="r_knee_y_link"/>
              <body name="r_ankle_y_link" pos="0 0 -0.3" gravcomp="0">
                <inertial pos="0 0 0" quat="0.5 0.5 -0.5 0.5" mass="0.0230716" diaginertia="3.67e-06 2.87e-06 1.54e-06"/>
                <joint name="r_ankle_y_joint" pos="0 0 0" axis="0 1 0" range="-1.134 0.872"/>
                <body name="r_ankle_x_link" pos="0 0 0" gravcomp="0">
                  <inertial pos="-0.00029962 0 -0.0261501" quat="0 0.708307 0 0.705905" mass="0.364824" diaginertia="0.00110975 0.00091946 0.00022373"/>
                  <joint name="r_ankle_x_joint" pos="0 0 0" axis="1 0 0" range="-0.349 0.349"/>
                  <geom class="collision" name="r_foot_1" size="0.01 0.085" pos="0 0.04 -0.03" quat="0.707105 0 0.707108 0" type="capsule" rgba="0.752941 0.752941 0.752941 1"/>
                  <geom class="collision" name="r_foot_2" size="0.01 0.085" pos="0 -0.04 -0.03" quat="0.707105 0 0.707108 0" type="capsule" rgba="0.752941 0.752941 0.752941 1"/>
                  <!-- <site name="rf_tc" type="box" size="0.09 0.043 0.005" pos="0.0 0 -0.035" rgba="1 1 1 1" /> -->
                  <site name="rf_tc" type="box" size="0.09 0.043 0.005" pos="0.0 0 -0.035" rgba="0 0 0 0"/>
                </body>
              </body>
            </body>
          </body>
        </body>
      </body>
      <body name="l_shld_y_link" pos="0 0.213 0.1521" gravcomp="0">
        <inertial pos="-0.00060202 -0.00203254 5.251e-05" quat="0.541376 0.518314 -0.463989 0.472203" mass="0.397431" diaginertia="0.00021153 0.000207788 0.000179523"/>
        <joint name="l_shld_y_joint" pos="0 0 0" axis="0 1 0" range="-1.5 1.5"/>
        <geom type="mesh" rgba="0.752941 0.752941 0.752941 1" mesh="l_shld_y_link"/>
        <body name="l_shld_x_link" pos="0 0 0" gravcomp="0">
          <inertial pos="3.499e-05 5.812e-05 -0.0683282" quat="0.708889 0.0252855 0.0274102 0.704333" mass="0.621968" diaginertia="0.000750759 0.00058036 0.000541362"/>
          <joint name="l_shld_x_joint" pos="0 0 0" axis="1 0 0" range="-0.52 2"/>
          <geom type="mesh" rgba="0.752941 0.752941 0.752941 1" mesh="l_shld_x_link"/>
          <body name="l_shld_z_link" pos="0 0 0" gravcomp="0">
            <inertial pos="8.049e-05 -0.00042451 -0.230839" quat="0.996174 -0.00232875 0.000739764 0.0873528" mass="0.449112" diaginertia="0.000744136 0.000739336 0.000232208"/>
            <joint name="l_shld_z_joint" pos="0 0 0" axis="0 0 1" range="-1.5 1.5"/>
            <geom type="mesh" rgba="0.752941 0.752941 0.752941 1" mesh="l_shld_z_link"/>
            <body name="l_elb_y_link" pos="0 0 -0.24505" gravcomp="0">
              <inertial pos="0 0.00061624 -0.10844" quat="0.999981 -0.00618255 0 0" mass="0.164833" diaginertia="0.00104575 0.00101134 0.000120034"/>
              <joint name="l_elb_y_joint" pos="0 0 0" axis="0 1 0" range="-2 0"/>
              <geom type="mesh" rgba="0.752941 0.752941 0.752941 1" mesh="l_elb_y_link"/>
            </body>
          </body>
        </body>
      </body>
      <body name="r_shld_y_link" pos="0 -0.213 0.1521" gravcomp="0">
        <inertial pos="-0.00060201 0.00203252 5.251e-05" quat="0.518418 0.541312 -0.472275 0.463877" mass="0.39743" diaginertia="0.00021153 0.000207787 0.000179523"/>
        <joint name="r_shld_y_joint" pos="0 0 0" axis="0 1 0" range="-1.5 1.5"/>
        <geom type="mesh" rgba="1 1 1 1" mesh="r_shld_y_link"/>
        <body name="r_shld_x_link" pos="0 0 0" gravcomp="0">
          <inertial pos="3.499e-05 -5.812e-05 -0.0683282" quat="0.704333 0.0274102 0.0252855 0.708889" mass="0.621968" diaginertia="0.000750759 0.00058036 0.000541362"/>
          <joint name="r_shld_x_joint" pos="0 0 0" axis="1 0 0" range="-2 0.52"/>
          <geom type="mesh" rgba="0.752941 0.752941 0.752941 1" mesh="r_shld_x_link"/>
          <body name="r_shld_z_link" pos="0 0 0" gravcomp="0">
            <inertial pos="8.059e-05 0.00042451 -0.230839" quat="0.996174 0.00232875 0.000739764 -0.0873528" mass="0.449113" diaginertia="0.000744136 0.000739336 0.000232208"/>
            <joint name="r_shld_z_joint" pos="0 0 0" axis="0 0 1" range="-1.5 1.5"/>
            <geom type="mesh" rgba="0.752941 0.752941 0.752941 1" mesh="r_shld_z_link"/>
            <body name="r_elb_y_link" pos="0 0 -0.24505" gravcomp="0">
              <inertial pos="0 -0.00061624 -0.10844" quat="0.999981 0.00617695 0 0" mass="0.164833" diaginertia="0.00104575 0.00101134 0.000120034"/>
              <joint name="r_elb_y_joint" pos="0 0 0" axis="0 1 0" range="-2 0"/>
              <geom type="mesh" rgba="0.752941 0.752941 0.752941 1" mesh="r_elb_y_link"/>
            </body>
          </body>
        </body>
      </body>
    </body>
  </worldbody>

  <actuator>

    <!-- <motor name="l_hip_z_joint" joint="l_hip_z_joint" gear="1" ctrllimited='false' ctrlrange='-6 6' />
    <motor name="l_hip_x_joint" joint="l_hip_x_joint" gear="1" ctrllimited='false' ctrlrange='-8 8' />
    <motor name="l_hip_y_joint" joint="l_hip_y_joint" gear="1" ctrllimited='false' ctrlrange='-10 10' />
    <motor name="l_knee_y_joint" joint="l_knee_y_joint" gear="1" ctrllimited='false' ctrlrange='-20 20' />
    <motor name="l_ankle_y_joint" joint="l_ankle_y_joint" gear="1" ctrllimited='false' ctrlrange='-6 6' />
    <motor name="l_ankle_x_joint" joint="l_ankle_x_joint" gear="1" ctrllimited='false' ctrlrange='-3 3' />

    <motor name="r_hip_z_joint" joint="r_hip_z_joint" gear="1" ctrllimited='false' ctrlrange='-6 6' />
    <motor name="r_hip_x_joint" joint="r_hip_x_joint" gear="1" ctrllimited='false' ctrlrange='-8 8' />
    <motor name="r_hip_y_joint" joint="r_hip_y_joint" gear="1" ctrllimited='false' ctrlrange='-10 10' />
    <motor name="r_knee_y_joint" joint="r_knee_y_joint" gear="1" ctrllimited='false' ctrlrange='-20 20' />
    <motor name="r_ankle_y_joint" joint="r_ankle_y_joint" gear="1" ctrllimited='false' ctrlrange='-6 6' />
    <motor name="r_ankle_x_joint" joint="r_ankle_x_joint" gear="1" ctrllimited='false' ctrlrange='-3 3' />

    <motor name="l_shld_y_joint" joint="l_shld_y_joint" gear="1" ctrllimited='false' ctrlrange='-7 7' />
    <motor name="l_shld_x_joint" joint="l_shld_x_joint" gear="1" ctrllimited='false' ctrlrange='-7 7' />
    <motor name="l_shld_z_joint" joint="l_shld_z_joint" gear="1" ctrllimited='false' ctrlrange='-7 7' />
    <motor name="l_elb_y_joint" joint="l_elb_y_joint" gear="1" ctrllimited='false' ctrlrange='-7 7' />
    <motor name="r_shld_y_joint" joint="r_shld_y_joint" gear="1" ctrllimited='false' ctrlrange='-7 7' />
    <motor name="r_shld_x_joint" joint="r_shld_x_joint" gear="1" ctrllimited='false' ctrlrange='-7 7' />
    <motor name="r_shld_z_joint" joint="r_shld_z_joint" gear="1" ctrllimited='false' ctrlrange='-7 7' />
    <motor name="r_elb_y_joint" joint="r_elb_y_joint" gear="1" ctrllimited='false' ctrlrange='-7 7' /> -->

    <motor name="l_hip_z_joint" joint="l_hip_z_joint" gear="1" ctrllimited='true' ctrlrange='-20 20' />
    <motor name="l_hip_x_joint" joint="l_hip_x_joint" gear="1" ctrllimited='true' ctrlrange='-40 40' />
    <motor name="l_hip_y_joint" joint="l_hip_y_joint" gear="1" ctrllimited='true' ctrlrange='-100 100' />
    <motor name="l_knee_y_joint" joint="l_knee_y_joint" gear="1" ctrllimited='true' ctrlrange='-120 120' />
    <motor name="l_ankle_y_joint" joint="l_ankle_y_joint" gear="1" ctrllimited='true' ctrlrange='-12 12' />
    <motor name="l_ankle_x_joint" joint="l_ankle_x_joint" gear="1" ctrllimited='true' ctrlrange='-6 6' />

    <motor name="r_hip_z_joint" joint="r_hip_z_joint" gear="1" ctrllimited='true' ctrlrange='-20 20' />
    <motor name="r_hip_x_joint" joint="r_hip_x_joint" gear="1" ctrllimited='true' ctrlrange='-40 40' />
    <motor name="r_hip_y_joint" joint="r_hip_y_joint" gear="1" ctrllimited='true' ctrlrange='-100 100' />
    <motor name="r_knee_y_joint" joint="r_knee_y_joint" gear="1" ctrllimited='true' ctrlrange='-120 120' />
    <motor name="r_ankle_y_joint" joint="r_ankle_y_joint" gear="1" ctrllimited='true' ctrlrange='-12 12' />
    <motor name="r_ankle_x_joint" joint="r_ankle_x_joint" gear="1" ctrllimited='true' ctrlrange='-6 6' />

    <motor name="l_shld_y_joint" joint="l_shld_y_joint" gear="1" ctrllimited='true' ctrlrange='-27 27' />
    <motor name="l_shld_x_joint" joint="l_shld_x_joint" gear="1" ctrllimited='true' ctrlrange='-27 27' />
    <motor name="l_shld_z_joint" joint="l_shld_z_joint" gear="1" ctrllimited='true' ctrlrange='-7 7' />
    <motor name="l_elb_y_joint" joint="l_elb_y_joint" gear="1" ctrllimited='true' ctrlrange='-27 27' />
    <motor name="r_shld_y_joint" joint="r_shld_y_joint" gear="1" ctrllimited='true' ctrlrange='-27 27' />
    <motor name="r_shld_x_joint" joint="r_shld_x_joint" gear="1" ctrllimited='true' ctrlrange='-27 27' />
    <motor name="r_shld_z_joint" joint="r_shld_z_joint" gear="1" ctrllimited='true' ctrlrange='-7 7' />
    <motor name="r_elb_y_joint" joint="r_elb_y_joint" gear="1" ctrllimited='true' ctrlrange='-27 27' />


  </actuator>

  <sensor>
    <framequat name="Body_Quat" objtype="site" objname="imu" />
    <gyro name="Body_Gyro" site="imu" />
    <accelerometer name="Body_Acc" site="imu" />

    <jointpos name="l_hip_z_joint_pos" joint="l_hip_z_joint" />
    <jointpos name="l_hip_x_joint_pos" joint="l_hip_x_joint" />
    <jointpos name="l_hip_y_joint_pos" joint="l_hip_y_joint" />
    <jointpos name="l_knee_y_joint_pos" joint="l_knee_y_joint" />
    <jointpos name="l_ankle_y_joint_pos" joint="l_ankle_y_joint" />
    <jointpos name="l_ankle_x_joint_pos" joint="l_ankle_x_joint" />

    <jointpos name="r_hip_z_joint_pos" joint="r_hip_z_joint" />
    <jointpos name="r_hip_x_joint_pos" joint="r_hip_x_joint" />
    <jointpos name="r_hip_y_joint_pos" joint="r_hip_y_joint" />
    <jointpos name="r_knee_y_joint_pos" joint="r_knee_y_joint" />
    <jointpos name="r_ankle_y_joint_pos" joint="r_ankle_y_joint" />
    <jointpos name="r_ankle_x_joint_pos" joint="r_ankle_x_joint" />

    <jointpos name="l_shld_y_joint_pos" joint="l_shld_y_joint" />
    <jointpos name="l_shld_x_joint_pos" joint="l_shld_x_joint" />
    <jointpos name="l_shld_z_joint_pos" joint="l_shld_z_joint" />
    <jointpos name="l_elb_y_joint_pos" joint="l_elb_y_joint" />
    <jointpos name="r_shld_y_joint_pos" joint="r_shld_y_joint" />
    <jointpos name="r_shld_x_joint_pos" joint="r_shld_x_joint" />
    <jointpos name="r_shld_z_joint_pos" joint="r_shld_z_joint" />
    <jointpos name="r_elb_y_joint_pos" joint="r_elb_y_joint" />


    <jointvel name="l_hip_z_joint_vel" joint="l_hip_z_joint" />
    <jointvel name="l_hip_x_joint_vel" joint="l_hip_x_joint" />
    <jointvel name="l_hip_y_joint_vel" joint="l_hip_y_joint" />
    <jointvel name="l_knee_y_joint_vel" joint="l_knee_y_joint" />
    <jointvel name="l_ankle_y_joint_vel" joint="l_ankle_y_joint" />
    <jointvel name="l_ankle_x_joint_vel" joint="l_ankle_x_joint" />

    <jointvel name="r_hip_z_joint_vel" joint="r_hip_z_joint" />
    <jointvel name="r_hip_x_joint_vel" joint="r_hip_x_joint" />
    <jointvel name="r_hip_y_joint_vel" joint="r_hip_y_joint" />
    <jointvel name="r_knee_y_joint_vel" joint="r_knee_y_joint" />
    <jointvel name="r_ankle_y_joint_vel" joint="r_ankle_y_joint" />
    <jointvel name="r_ankle_x_joint_vel" joint="r_ankle_x_joint" />

    <jointpos name="l_shld_y_joint_vel" joint="l_shld_y_joint" />
    <jointpos name="l_shld_x_joint_vel" joint="l_shld_x_joint" />
    <jointpos name="l_shld_z_joint_vel" joint="l_shld_z_joint" />
    <jointpos name="l_elb_y_joint_vel" joint="l_elb_y_joint" />
    <jointpos name="r_shld_y_joint_vel" joint="r_shld_y_joint" />
    <jointpos name="r_shld_x_joint_vel" joint="r_shld_x_joint" />
    <jointpos name="r_shld_z_joint_vel" joint="r_shld_z_joint" />
    <jointpos name="r_elb_y_joint_vel" joint="r_elb_y_joint" />

    <touch name="lf_touch" site="lf_tc" />
    <touch name="rf_touch" site="rf_tc" />
  </sensor>

</mujoco>
